Workbook

Sheet 입력 시트
B2: 고객명 | C2: 정재성 | F2: 작성일자 | G2: 46237
B3: 구분 | C3: 개인사업자 | F3: 지역 | G3: 경기 군포시
B4: 소상공인 | C4: O | F4: 면세구분 | G4: 일반인
B5: 경유차 폐차여부 | C5: 경유차 유지 후 전기차 전환 | F5: 선수금 | G5: 0.3
B6: 화물자동차 운송사업허가증 | C6: O | F6: 할부개월수 | G6: 60
B7: 영업용 번호판 보유 | C7: O
B9: 차량/특장 옵션 (VAT 포함)
B10: 차량 | C10: PV5 | D10: 플러스
B11: 특장 | C11: 탑 종류 | D11: 냉장/냉동
C12: 탑 높이 | D12: 저상
C13: 스포일러 | D13: X
C14: 도어옵션 | D14: 슬라이딩
C15: 도어추가 | D15: O
C16: 온도기록계 | D16: O
C17: 격벽 | D17: 냉장/냉동 이동식

Sheet 차량견적서
A1: STEGO K_견적서 | H1: ="작업 날짜 : " & TEXT('입력 시트'!G2, "YYYY-MM-DD") -> 작업 날짜 : 2026-08-03
A2: ='입력 시트'!C2& " 고객님, 만나서 반갑습니다. 고객님의 즐거운 여정에 늘 함께 하겠습니다." -> 정재성 고객님, 만나서 반갑습니다. 고객님의 즐거운 여정에 늘 함께 하겠습니다. | Q2: : BuildUP-EV 입력
Q3: : DB + 수식
A4: ="STEGO-K1 : PV5 " & '입력 시트'!D10 & " " & '입력 시트'!D11 & "탑차 - " & '입력 시트'!D12 -> STEGO-K1 : PV5 플러스 냉장/냉동탑차 - 저상 | Q4: : DB
B5: {="특장 옵션 : " & _xlfn.TEXTJOIN(" , ", TRUE, '입력 시트'!C11:C17 & " = " & '입력 시트'!D11:D17)} -> 특장 옵션 : 탑 종류 = 냉장/냉동 , 탑 높이 = 저상 , 스포일러 = X , 도어옵션 = 슬라이딩 , 도어추가 = O , 온도기록계 = O , 격벽 = 냉장/냉동 이동식 | Q5: : 수식
Q6: : 고정
A8: 차량 정보 | F8: 특장 정보 | K8: 고객 정보
K9: 고객명 | M9: ='입력 시트'!C2 -> 정재성
A10: ① 차량 가격 | D10: =_xlfn.XLOOKUP('입력 시트'!D10, 옵션DB!Q2:Q3, 옵션DB!R2:R3, 0) -> 49650000 | F10: ="탑 종류 : " & '입력 시트'!D11 & " " &'입력 시트'!D12 -> 탑 종류 : 냉장/냉동 저상 | I10: =_xlfn.XLOOKUP('입력 시트'!D11&'입력 시트'!D12,옵션DB!A2:A5,옵션DB!B2:B5) -> 19320000 | K10: 구분 | M10: ='입력 시트'!C3 -> 개인사업자
A11: ② 탁송료 | D11: =옵션DB!X4 -> 188000 | F11: ="스포일러 : " & '입력 시트'!D13 -> 스포일러 : X | I11: =_xlfn.XLOOKUP('입력 시트'!D13,옵션DB!T2:T3,옵션DB!U2:U3) -> 0 | K11: 지역 | M11: ='입력 시트'!G3 -> 경기 군포시
A12: 현대커머셜 할인 | D12: =옵션DB!X2 -> 700000 | F12: ="도어옵션 : " & '입력 시트'!D14 -> 도어옵션 : 슬라이딩 | I12: =_xlfn.XLOOKUP('입력 시트'!D11&'입력 시트'!D12&'입력 시트'!D14,옵션DB!D2:D17,옵션DB!E2:E17) -> 308000 | K12: 소상공인 | M12: ='입력 시트'!C4 -> O
A13: 공식 파트너십 할인 | D13: =(D10-D12)*0.01 -> 489500 | F13: ="도어추가 : " & '입력 시트'!D15 -> 도어추가 : O | I13: =_xlfn.XLOOKUP('입력 시트'!D11&'입력 시트'!D12&'입력 시트'!D14&'입력 시트'!D15,옵션DB!G2:G17,옵션DB!H2:H17,0) -> 836000 | K13: 화물자동차 운송사업허가증 | M13: ='입력 시트'!C6 -> O
A14: ③ 구매 혜택 | D14: =-SUM(D12:D13) -> -1189500 | F14: ="온도기록계 : " & '입력 시트'!D16 -> 온도기록계 : O | I14: =_xlfn.XLOOKUP('입력 시트'!C16&'입력 시트'!D16,옵션DB!J8:J9,옵션DB!K8:K9) -> 495000 | K14: 경유차 폐차여부 | M14: ='입력 시트'!C5 -> 경유차 유지 후 전기차 전환
A15: 국고보조금 (정부) | D15: =IF('입력 시트'!C5="경유차 유지 후 전기차 전환",옵션DB!AA2-500000,옵션DB!AA2) -> 11000000 | F15: ="격벽 : " & '입력 시트'!D17 -> 격벽 : 냉장/냉동 이동식 | I15: =_xlfn.XLOOKUP('입력 시트'!D12&'입력 시트'!C17&'입력 시트'!D17,옵션DB!J2:J7,옵션DB!K2:K7) -> 660000 | K15: 영업용 번호판 보유 | M15: ='입력 시트'!C7 -> O
A16: ="지방보조금 (" &'입력 시트'!G3&")" -> 지방보조금 (경기 군포시) | D16: =IF('입력 시트'!C3="법인사업자",0,_xlfn.XLOOKUP('입력 시트'!G3,옵션DB!M2:M162,옵션DB!N2:N162)) -> 5290000 | F16: ⑦ 특장 가격 (VAT 포함) | I16: =SUM(I10:I15) -> 21619000 | K16: 선수금 | M16: ='입력 시트'!G5 -> 0.3
A17: 소상공인 할인 | D17: =IF('입력 시트'!C4="O",차량견적서!D15*0.3,0) -> 3300000 | F17: 프로모션 | I17: 0 | K17: 할부 | L17: 차량 | M17: 특장
A18: 택배업 보조금 (화물운송자격) | D18: =IF(AND('입력 시트'!C3="개인사업자",'입력 시트'!C6="O"),차량견적서!D15*0.1,0) -> 1100000 | F18: ⑧ 프로모션 | I18: =SUM(I17) -> 0 | K18: 할부금 | L18: =D20-D23 -> 13135250 | M18: =I20-I23 -> 21219000
A19: ④ EV보조금 합계 | D19: =-SUM(D15:D18) -> -20690000 | K19: 총할부금 | L19: =L18+M18 -> 34354250
A20: 차량 결제 금액 (①+②-③-④) | D20: =D10+D11+D14+D19 -> 27958500 | F20: 특장 결제 금액 (⑦-⑧) | I20: =I16-I18 -> 21619000 | K20: 상품명 | L20: 일반형 오토론할부
A21: 계약금 | D21: 100000 | F21: 계약금 | I21: 400000 | K21: 이율 | M21: =_xlfn.XLOOKUP('입력 시트'!G6,옵션DB!AF2:AF5,옵션DB!AG2:AG5) -> 0.066
A22: 선수금 | D22: =(D20+I20-D21-I21)*'입력 시트'!G5 -> 14723250 | K22: 할부이자 | M22: =M24*M23-L19 -> 6073189.9
A23: ⑤ 인도금(차량) (차량구매금액-할부) | D23: =D21+D22 -> 14823250 | F23: ⑨ 인도금(특장) (특장구매금액-할부) | I23: =I21+I22 -> 400000 | K23: 이용기간 | M23: ='입력 시트'!G6 -> 60
A24: 차량 취득세 | D24: =IF('입력 시트'!C7="O",ROUNDDOWN(((D10+D11+D14)/11*10*0.04)-1400000,-1),ROUNDDOWN(((D10+D11+D14)/11*10*0.05)-1400000,-1)) -> 369030 | F24: 특장 취득세 (2.0%) | I24: =ROUNDDOWN(I20*0.02,-1) -> 432380 | K24: 월 납입금 | M24: =PMT(M21/12,M23,-L19) -> 673790.66
A25: 공채할인액 | D25: =IF(AND('입력 시트'!G4="일반인",'입력 시트'!G3="서울특별시"),옵션DB!X9,0) -> 0 | F25: 등록부가수수료 | I25: =옵션DB!AD2 -> 50000
A26: 번호판금액 | D26: =옵션DB!X6 -> 28000 | K26: 부가세 환급 시 가격 | M26: =ROUNDDOWN((D20+I20)/11*10,-1) -> 45070450
A27: 증지대 | D27: =옵션DB!X5 -> 2000 | K27: 메모/안내문
A28: 의무보험료 | D28: =옵션DB!X8 -> 2800 | K28: · 서비스 : 블랙박스, 썬팅, 온도기록계, 운전석 측 도어 추가
A29: 등록대행료 | D29: =옵션DB!X7 -> 30000 | K29: 고객님께서 꼭 알아두셔야 할 사항
A30: ⑥ 등록/부대비용 | D30: =SUM(D24:D29) -> 431830 | F30: ⑩ 등록/부대비용 | I30: =SUM(I24:I25) -> 482380 | K30: · 탁송료 및 보조금 등은 차량 출고 시점에 따라 변경될 수 있습니다.
A31: 차량 초기 납부 금액 (⑤ + ⑥) | D31: =D23+D30 -> 15255080 | F31: 특장 초기 납부 금액 (⑨+⑩) | I31: =I23+I30 -> 882380 | K31: · 당사의 프로모션은 매달 변경될 수 있습니다.

Sheet 옵션DB
A1: [ 특장 옵션(적재함 사양)(VAT 포함) ] | D1: [ 특장 옵션(도어 종류)(VAT 포함) ] | G1: [ 특장 옵션(도어 추가)(VAT 포함) ] | J1: [ 특장 옵션(기타)(VAT 포함) ] | M1: 지역 | N1: 보조금 | O1: 탁송료 | Q1: [ 차량 옵션(VAT 포함) ] | T1: [ 스포일러(VAT 포함) ] | W1: [KIA 견적서 변동사항] | Z1: [국고보조금] | AC1: [EV 견적서 변동사항] | AF1: [할부개월수]
A2: 내장저상 | B2: 9310000 | D2: 냉장/냉동저상여닫이 | E2: 0 | G2: 냉장/냉동저상여닫이O | H2: =480000*1.1 -> 528000 | J2: 표준격벽그물망 | K2: =170000*1.1 -> 187000 | M2: 강원 강릉시 | N2: 4600000 | O2: 580000 | Q2: 베이직 | R2: 46530000 | T2: O | U2: 440000 | W2: 현대커머셜 할인 | X2: 700000 | Z2: 국고보조금 | AA2: 11500000 | AC2: 등록부가수수료 | AD2: 50000 | AF2: 일시불 | AG2: 0
A3: 내장표준 | B3: 9530000 | D3: 냉장/냉동저상슬라이딩 | E3: =280000*1.1 -> 308000 | G3: 냉장/냉동저상슬라이딩O | H3: =760000*1.1 -> 836000 | J3: 저상격벽그물망 | K3: =170000*1.1 -> 187000 | M3: 강원 고성군 | N3: 4600000 | O3: 630000 | Q3: 플러스 | R3: 49650000 | T3: X | U3: 0 | W3: 공식 파트너십 할인 | AF3: 36 | AG3: 0.064
A4: 냉장/냉동저상 | B4: 19320000 | D4: 냉장/냉동저상EV미닫이(냉동전용) | E4: =1600000*1.1 -> 1760000 | G4: 냉장/냉동저상EV미닫이(냉동전용)O | H4: =1600000*1.1 -> 1760000 | J4: 표준격벽냉장/냉동 이동식 | K4: =650000*1.1 -> 715000 | M4: 강원 동해시 | N4: 4600000 | O4: 620000 | W4: 탁송료 | X4: 188000 | AF4: 48 | AG4: 0.066
A5: 냉장/냉동표준 | B5: 19650000 | D5: 냉장/냉동저상쿠팡미닫이(내장전용) | E5: 0 | G5: 냉장/냉동저상쿠팡미닫이(내장전용)O | H5: 0 | J5: 저상격벽냉장/냉동 이동식 | K5: =600000*1.1 -> 660000 | M5: 강원 삼척시 | N5: 4600000 | O5: 640000 | W5: 증지대 | X5: 2000 | AF5: 60 | AG5: 0.066
D6: 냉장/냉동표준여닫이 | E6: 0 | G6: 냉장/냉동표준여닫이O | H6: =520000*1.1 -> 572000 | J6: 표준격벽X | K6: 0 | M6: 강원 속초시 | N6: 4600000 | O6: 600000 | W6: 번호판금액 | X6: 28000
D7: 냉장/냉동표준슬라이딩 | E7: =300000*1.1 -> 330000 | G7: 냉장/냉동표준슬라이딩O | H7: =820000*1.1 -> 902000 | J7: 저상격벽X | K7: 0 | M7: 강원 양구군 | N7: 4600000 | O7: 510000 | W7: 등록대행료 | X7: 30000
D8: 냉장/냉동표준EV미닫이(냉동전용) | E8: =1800000*1.1 -> 1980000 | G8: 냉장/냉동표준EV미닫이(냉동전용)O | H8: =1800000*1.1 -> 1980000 | J8: 온도기록계O | K8: =450000*1.1 -> 495000 | M8: 강원 양양군 | N8: 4600000 | O8: 590000 | W8: 의무보험료 | X8: 2800
D9: 냉장/냉동표준쿠팡미닫이(내장전용) | E9: 0 | G9: 냉장/냉동표준쿠팡미닫이(내장전용)O | H9: 0 | J9: 온도기록계X | K9: 0 | M9: 강원 영월군 | N9: 4600000 | O9: 520000 | W9: 공채할인액 | X9: 31648
D10: 내장저상여닫이 | E10: 0 | G10: 내장저상여닫이O | H10: =380000*1.1 -> 418000 | M10: 강원 원주시 | N10: 4600000 | O10: 410000
D11: 내장저상슬라이딩 | E11: =280000*1.1 -> 308000 | G11: 내장저상슬라이딩O | H11: =660000*1.1 -> 726000 | M11: 강원 인제군 | N11: 4600000 | O11: 530000
D12: 내장저상EV미닫이(냉동전용) | E12: 0 | G12: 내장저상EV미닫이(냉동전용)O | H12: 0 | M12: 강원 정선군 | N12: 4600000 | O12: 580000
D13: 내장저상쿠팡미닫이(내장전용) | E13: =900000*1.1 -> 990000 | G13: 내장저상쿠팡미닫이(내장전용)O | H13: =900000*1.1 -> 990000 | M13: 강원 철원군 | N13: 4600000 | O13: 480000
D14: 내장표준여닫이 | E14: 0 | G14: 내장표준여닫이O | H14: =400000*1.1 -> 440000 | M14: 강원 춘천시 | N14: 4600000 | O14: 440000
D15: 내장표준슬라이딩 | E15: =300000*1.1 -> 330000 | G15: 내장표준슬라이딩O | H15: =700000*1.1 -> 770000 | I15: {=_xlfn.XLOOKUP('입력 시트'!D12&'입력 시트'!C17&'입력 시트'!D17,옵션DB!D10,옵션DB!K2:K5)} -> #N/A | M15: 강원 태백시 | N15: 4600000 | O15: 640000
D16: 내장표준EV미닫이(냉동전용) | E16: 0 | G16: 내장표준EV미닫이(냉동전용)O | H16: 0 | M16: 강원 평창군 | N16: 4600000 | O16: 540000
D17: 내장표준쿠팡미닫이(내장전용) | E17: =1000000*1.1 -> 1100000 | G17: 내장표준쿠팡미닫이(내장전용)O | H17: =1000000*1.1 -> 1100000 | M17: 강원 홍천군 | N17: 4600000 | O17: 460000
M18: 강원 화천군 | N18: 4600000 | O18: 490000
M19: 강원 횡성군 | N19: 4600000 | O19: 440000
M20: 경기 가평군 | N20: 6440000 | O20: 380000
M21: 경기 고양시 | N21: 3450000 | O21: 340000
M22: 경기 과천시 | N22: 6900000 | O22: 310000
M23: 경기 광명시 | N23: 6550000 | O23: 310000
M24: 경기 광주시 | N24: 4600000 | O24: 310000
M25: 경기 구리시 | N25: 5750000 | O25: 340000
M26: 경기 군포시 | N26: 5290000 | O26: 280000
M27: 경기 김포시 | N27: 4600000 | O27: 340000
M28: 경기 남양주시 | N28: 3450000 | O28: 350000
M29: 경기 동두천시 | N29: 5750000 | O29: 380000
... M90: 경북 포항시 | N90: 6560000 | O90: 630000
M91: 공단 한국환경공단 | N91: 0
M92: 광주광역시 | N92: 3450000 | O92: 560000
M93: 대구광역시 | N93: 3450000 | O93: 540000
M94: 대전광역시 | N94: 3450000 | O94: 420000
M95: 부산광역시 | N95: 3450000 | O95: 680000
M96: 서울특별시 | N96: 3300000 | O96: 325000
M97: 세종특별자치시 | N97: 3450000 | O97: 390000
M98: 울산광역시 | N98: 3450000 | O98: 660000
M99: 인천광역시 | N99: 3450000 | O99: 325000
M100: 전남 강진군 | N100: 8050000 | O100: 660000
...
